2021-09-10 23:00:00,351 ERROR: Exception on /auth/reset_password_request [POST] [in /Users/ozanunal/Desktop/Python/microblog/flask/lib/python3.9/site-packages/flask/app.py:1454]
Traceback (most recent call last):
  File "/Users/ozanunal/Desktop/Python/microblog/flask/lib/python3.9/site-packages/sqlalchemy/engine/base.py", line 1770, in _execute_context
    self.dialect.do_execute(
  File "/Users/ozanunal/Desktop/Python/microblog/flask/lib/python3.9/site-packages/sqlalchemy/engine/default.py", line 717, in do_execute
    cursor.execute(statement, parameters)
sqlite3.OperationalError: no such table: user

The above exception was the direct cause of the following exception:

Traceback (most recent call last):
  File "/Users/ozanunal/Desktop/Python/microblog/flask/lib/python3.9/site-packages/flask/app.py", line 2070, in wsgi_app
    response = self.full_dispatch_request()
  File "/Users/ozanunal/Desktop/Python/microblog/flask/lib/python3.9/site-packages/flask/app.py", line 1515, in full_dispatch_request
    rv = self.handle_user_exception(e)
  File "/Users/ozanunal/Desktop/Python/microblog/flask/lib/python3.9/site-packages/flask/app.py", line 1513, in full_dispatch_request
    rv = self.dispatch_request()
  File "/Users/ozanunal/Desktop/Python/microblog/flask/lib/python3.9/site-packages/flask/app.py", line 1499, in dispatch_request
    return self.ensure_sync(self.view_functions[rule.endpoint])(**req.view_args)
  File "/Users/ozanunal/Desktop/Python/microblog/app/auth/routes.py", line 59, in reset_password_request
    user = User.query.filter_by(email=form.email.data).first()
  File "/Users/ozanunal/Desktop/Python/microblog/flask/lib/python3.9/site-packages/sqlalchemy/orm/query.py", line 2760, in first
    return self.limit(1)._iter().first()
  File "/Users/ozanunal/Desktop/Python/microblog/flask/lib/python3.9/site-packages/sqlalchemy/orm/query.py", line 2844, in _iter
    result = self.session.execute(
  File "/Users/ozanunal/Desktop/Python/microblog/flask/lib/python3.9/site-packages/sqlalchemy/orm/session.py", line 1689, in execute
    result = conn._execute_20(statement, params or {}, execution_options)
  File "/Users/ozanunal/Desktop/Python/microblog/flask/lib/python3.9/site-packages/sqlalchemy/engine/base.py", line 1582, in _execute_20
    return meth(self, args_10style, kwargs_10style, execution_options)
  File "/Users/ozanunal/Desktop/Python/microblog/flask/lib/python3.9/site-packages/sqlalchemy/sql/elements.py", line 323, in _execute_on_connection
    return connection._execute_clauseelement(
  File "/Users/ozanunal/Desktop/Python/microblog/flask/lib/python3.9/site-packages/sqlalchemy/engine/base.py", line 1451, in _execute_clauseelement
    ret = self._execute_context(
  File "/Users/ozanunal/Desktop/Python/microblog/flask/lib/python3.9/site-packages/sqlalchemy/engine/base.py", line 1813, in _execute_context
    self._handle_dbapi_exception(
  File "/Users/ozanunal/Desktop/Python/microblog/flask/lib/python3.9/site-packages/sqlalchemy/engine/base.py", line 1994, in _handle_dbapi_exception
    util.raise_(
  File "/Users/ozanunal/Desktop/Python/microblog/flask/lib/python3.9/site-packages/sqlalchemy/util/compat.py", line 207, in raise_
    raise exception
  File "/Users/ozanunal/Desktop/Python/microblog/flask/lib/python3.9/site-packages/sqlalchemy/engine/base.py", line 1770, in _execute_context
    self.dialect.do_execute(
  File "/Users/ozanunal/Desktop/Python/microblog/flask/lib/python3.9/site-packages/sqlalchemy/engine/default.py", line 717, in do_execute
    cursor.execute(statement, parameters)
sqlalchemy.exc.OperationalError: (sqlite3.OperationalError) no such table: user
[SQL: SELECT user.id AS user_id, user.username AS user_username, user.email AS user_email, user.password_hash AS user_password_hash, user.about_me AS user_about_me, user.last_seen AS user_last_seen, user.token AS user_token, user.token_expiration AS user_token_expiration, user.last_message_read_time AS user_last_message_read_time 
FROM user 
WHERE user.email = ?
 LIMIT ? OFFSET ?]
[parameters: ('ozanunal@protonmail.com', 1, 0)]
(Background on this error at: http://sqlalche.me/e/14/e3q8)
2021-09-10 23:00:20,747 INFO: Microblog startup [in /Users/ozanunal/Desktop/Python/microblog/app/__init__.py:89]
2021-09-10 23:00:46,251 INFO: Microblog startup [in /Users/ozanunal/Desktop/Python/microblog/app/__init__.py:89]
2021-09-10 23:01:00,790 INFO: Microblog startup [in /Users/ozanunal/Desktop/Python/microblog/app/__init__.py:89]
2021-09-10 23:01:16,259 INFO: Microblog startup [in /Users/ozanunal/Desktop/Python/microblog/app/__init__.py:89]
2021-09-10 23:01:23,458 INFO: Microblog startup [in /Users/ozanunal/Desktop/Python/microblog/app/__init__.py:89]
2021-09-10 23:02:13,540 ERROR: Exception on /export_posts [GET] [in /Users/ozanunal/Desktop/Python/microblog/flask/lib/python3.9/site-packages/flask/app.py:1454]
Traceback (most recent call last):
  File "/Users/ozanunal/Desktop/Python/microblog/flask/lib/python3.9/site-packages/redis/connection.py", line 559, in connect
    sock = self._connect()
  File "/Users/ozanunal/Desktop/Python/microblog/flask/lib/python3.9/site-packages/redis/connection.py", line 615, in _connect
    raise err
  File "/Users/ozanunal/Desktop/Python/microblog/flask/lib/python3.9/site-packages/redis/connection.py", line 603, in _connect
    sock.connect(socket_address)
ConnectionRefusedError: [Errno 61] Connection refused

During handling of the above exception, another exception occurred:

Traceback (most recent call last):
  File "/Users/ozanunal/Desktop/Python/microblog/flask/lib/python3.9/site-packages/flask/app.py", line 2070, in wsgi_app
    response = self.full_dispatch_request()
  File "/Users/ozanunal/Desktop/Python/microblog/flask/lib/python3.9/site-packages/flask/app.py", line 1515, in full_dispatch_request
    rv = self.handle_user_exception(e)
  File "/Users/ozanunal/Desktop/Python/microblog/flask/lib/python3.9/site-packages/flask/app.py", line 1513, in full_dispatch_request
    rv = self.dispatch_request()
  File "/Users/ozanunal/Desktop/Python/microblog/flask/lib/python3.9/site-packages/flask/app.py", line 1499, in dispatch_request
    return self.ensure_sync(self.view_functions[rule.endpoint])(**req.view_args)
  File "/Users/ozanunal/Desktop/Python/microblog/flask/lib/python3.9/site-packages/flask_login/utils.py", line 272, in decorated_view
    return func(*args, **kwargs)
  File "/Users/ozanunal/Desktop/Python/microblog/app/main/routes.py", line 213, in export_posts
    current_user.launch_task('export_posts', _('Exporting posts...'))
  File "/Users/ozanunal/Desktop/Python/microblog/app/models.py", line 176, in launch_task
    rq_job = current_app.task_queue.enqueue('app.tasks.' + name, self.id,
  File "/Users/ozanunal/Desktop/Python/microblog/flask/lib/python3.9/site-packages/rq/queue.py", line 502, in enqueue
    return self.enqueue_call(
  File "/Users/ozanunal/Desktop/Python/microblog/flask/lib/python3.9/site-packages/rq/queue.py", line 400, in enqueue_call
    return self.enqueue_job(job, pipeline=pipeline, at_front=at_front)
  File "/Users/ozanunal/Desktop/Python/microblog/flask/lib/python3.9/site-packages/rq/queue.py", line 560, in enqueue_job
    job.save(pipeline=pipe)
  File "/Users/ozanunal/Desktop/Python/microblog/flask/lib/python3.9/site-packages/rq/job.py", line 650, in save
    if self.get_redis_server_version() >= StrictVersion("4.0.0"):
  File "/Users/ozanunal/Desktop/Python/microblog/flask/lib/python3.9/site-packages/rq/job.py", line 658, in get_redis_server_version
    self.redis_server_version = get_version(self.connection)
  File "/Users/ozanunal/Desktop/Python/microblog/flask/lib/python3.9/site-packages/rq/utils.py", line 283, in get_version
    version_string = connection.info("server")["redis_version"]
  File "/Users/ozanunal/Desktop/Python/microblog/flask/lib/python3.9/site-packages/redis/client.py", line 1306, in info
    return self.execute_command('INFO', section)
  File "/Users/ozanunal/Desktop/Python/microblog/flask/lib/python3.9/site-packages/redis/client.py", line 898, in execute_command
    conn = self.connection or pool.get_connection(command_name, **options)
  File "/Users/ozanunal/Desktop/Python/microblog/flask/lib/python3.9/site-packages/redis/connection.py", line 1192, in get_connection
    connection.connect()
  File "/Users/ozanunal/Desktop/Python/microblog/flask/lib/python3.9/site-packages/redis/connection.py", line 563, in connect
    raise ConnectionError(self._error_message(e))
redis.exceptions.ConnectionError: Error 61 connecting to None:6379. Connection refused.
2021-09-10 23:03:15,529 INFO: Microblog startup [in /Users/ozanunal/Desktop/Python/flask_app/app/__init__.py:89]
