2021-09-05 00:25:20,889 ERROR: Exception on /index [GET] [in /Users/ozanunal/Desktop/Python/flask_app/flaskwork/lib/python3.8/site-packages/flask/app.py:1454]
Traceback (most recent call last):
  File "/Users/ozanunal/Desktop/Python/flask_app/flaskwork/lib/python3.8/site-packages/flask/app.py", line 2070, in wsgi_app
    response = self.full_dispatch_request()
  File "/Users/ozanunal/Desktop/Python/flask_app/flaskwork/lib/python3.8/site-packages/flask/app.py", line 1515, in full_dispatch_request
    rv = self.handle_user_exception(e)
  File "/Users/ozanunal/Desktop/Python/flask_app/flaskwork/lib/python3.8/site-packages/flask/app.py", line 1513, in full_dispatch_request
    rv = self.dispatch_request()
  File "/Users/ozanunal/Desktop/Python/flask_app/flaskwork/lib/python3.8/site-packages/flask/app.py", line 1499, in dispatch_request
    return self.ensure_sync(self.view_functions[rule.endpoint])(**req.view_args)
  File "/Users/ozanunal/Desktop/Python/flask_app/flaskwork/lib/python3.8/site-packages/flask_login/utils.py", line 272, in decorated_view
    return func(*args, **kwargs)
  File "/Users/ozanunal/Desktop/Python/flask_app/app/routes.py", line 40, in index
    return render_template('index.html', title='Home', form=form,
  File "/Users/ozanunal/Desktop/Python/flask_app/flaskwork/lib/python3.8/site-packages/flask/templating.py", line 147, in render_template
    return _render(
  File "/Users/ozanunal/Desktop/Python/flask_app/flaskwork/lib/python3.8/site-packages/flask/templating.py", line 128, in _render
    rv = template.render(context)
  File "/Users/ozanunal/Desktop/Python/flask_app/flaskwork/lib/python3.8/site-packages/jinja2/environment.py", line 1304, in render
    self.environment.handle_exception()
  File "/Users/ozanunal/Desktop/Python/flask_app/flaskwork/lib/python3.8/site-packages/jinja2/environment.py", line 925, in handle_exception
    raise rewrite_traceback_stack(source=source)
  File "/Users/ozanunal/Desktop/Python/flask_app/app/templates/index.html", line 1, in top-level template code
    {% extends "base.html" %}
  File "/Users/ozanunal/Desktop/Python/flask_app/flaskwork/lib/python3.8/site-packages/jinja2/environment.py", line 925, in handle_exception
    raise rewrite_traceback_stack(source=source)
  File "/Users/ozanunal/Desktop/Python/flask_app/app/templates/base.html", line 43, in template
    {% block scripts %}
jinja2.exceptions.TemplateAssertionError: block 'scripts' defined twice
2021-09-05 00:25:54,912 INFO: Microblog startup [in /Users/ozanunal/Desktop/Python/flask_app/app/__init__.py:38]
2021-09-05 00:28:02,746 INFO: Microblog startup [in /Users/ozanunal/Desktop/Python/flask_app/app/__init__.py:38]
2021-09-05 00:28:21,077 INFO: Microblog startup [in /Users/ozanunal/Desktop/Python/flask_app/app/__init__.py:38]
2021-09-05 00:28:55,578 INFO: Microblog startup [in /Users/ozanunal/Desktop/Python/flask_app/app/__init__.py:38]
2021-09-05 00:29:21,779 INFO: Microblog startup [in /Users/ozanunal/Desktop/Python/flask_app/app/__init__.py:38]
2021-09-05 00:29:42,080 INFO: Microblog startup [in /Users/ozanunal/Desktop/Python/flask_app/app/__init__.py:38]
